Traceback (most recent call last):
  File "C:\Users\dahoon\PycharmProjects\rental\rentalService\apps\item\itemManager.py", line 21, in regist
    item.save()
  File "C:\Users\dahoon\PycharmProjects\rental\venv\lib\site-packages\django\db\models\base.py", line 718, in save
    force_update=force_update, update_fields=update_fields)
  File "C:\Users\dahoon\PycharmProjects\rental\venv\lib\site-packages\django\db\models\base.py", line 748, in save_base
    updated = self._save_table(raw, cls, force_insert, force_update, using, update_fields)
  File "C:\Users\dahoon\PycharmProjects\rental\venv\lib\site-packages\django\db\models\base.py", line 812, in _save_table
    forced_update)
  File "C:\Users\dahoon\PycharmProjects\rental\venv\lib\site-packages\django\db\models\base.py", line 841, in _do_update
    filtered = base_qs.filter(pk=pk_val)
  File "C:\Users\dahoon\PycharmProjects\rental\venv\lib\site-packages\django\db\models\query.py", line 844, in filter
    return self._filter_or_exclude(False, *args, **kwargs)
  File "C:\Users\dahoon\PycharmProjects\rental\venv\lib\site-packages\django\db\models\query.py", line 862, in _filter_or_exclude
    clone.query.add_q(Q(*args, **kwargs))
  File "C:\Users\dahoon\PycharmProjects\rental\venv\lib\site-packages\django\db\models\sql\query.py", line 1263, in add_q
    clause, _ = self._add_q(q_object, self.used_aliases)
  File "C:\Users\dahoon\PycharmProjects\rental\venv\lib\site-packages\django\db\models\sql\query.py", line 1287, in _add_q
    split_subq=split_subq,
  File "C:\Users\dahoon\PycharmProjects\rental\venv\lib\site-packages\django\db\models\sql\query.py", line 1225, in build_filter
    condition = self.build_lookup(lookups, col, value)
  File "C:\Users\dahoon\PycharmProjects\rental\venv\lib\site-packages\django\db\models\sql\query.py", line 1096, in build_lookup
    lookup = lookup_class(lhs, rhs)
  File "C:\Users\dahoon\PycharmProjects\rental\venv\lib\site-packages\django\db\models\lookups.py", line 20, in __init__
    self.rhs = self.get_prep_lookup()
  File "C:\Users\dahoon\PycharmProjects\rental\venv\lib\site-packages\django\db\models\lookups.py", line 70, in get_prep_lookup
    return self.lhs.output_field.get_prep_value(self.rhs)
  File "C:\Users\dahoon\PycharmProjects\rental\venv\lib\site-packages\django\db\models\fields\__init__.py", line 965, in get_prep_value
    return int(value)
TypeError: int() argument must be a string, a bytes-like object or a number, not 'dict'

Traceback (most recent call last):
  File "C:\Users\dahoon\PycharmProjects\rental\rentalService\apps\item\itemManager.py", line 18, in regist
    picture=request.POST.get('img'),
  File "C:\Users\dahoon\PycharmProjects\rental\venv\lib\site-packages\django\db\models\base.py", line 485, in __init__
    raise TypeError("'%s' is an invalid keyword argument for this function" % kwarg)
TypeError: 'uid' is an invalid keyword argument for this function

Traceback (most recent call last):
  File "C:\Users\dahoon\PycharmProjects\rental\rentalService\apps\item\itemManager.py", line 18, in regist
    picture=request.POST.get('img'),
  File "C:\Users\dahoon\PycharmProjects\rental\venv\lib\site-packages\django\db\models\base.py", line 485, in __init__
    raise TypeError("'%s' is an invalid keyword argument for this function" % kwarg)
TypeError: 'maxRentDate' is an invalid keyword argument for this function

Traceback (most recent call last):
  File "C:\Users\dahoon\PycharmProjects\rental\rentalService\apps\item\itemManager.py", line 18, in regist
    picture=request.POST.get('img'),
  File "C:\Users\dahoon\PycharmProjects\rental\venv\lib\site-packages\django\db\models\base.py", line 485, in __init__
    raise TypeError("'%s' is an invalid keyword argument for this function" % kwarg)
TypeError: 'desc' is an invalid keyword argument for this function

Traceback (most recent call last):
  File "C:\Users\dahoon\PycharmProjects\rental\venv\lib\site-packages\django\db\backends\utils.py", line 85, in _execute
    return self.cursor.execute(sql, params)
  File "C:\Users\dahoon\PycharmProjects\rental\venv\lib\site-packages\django\db\backends\sqlite3\base.py", line 296, in execute
    return Database.Cursor.execute(self, query, params)
sqlite3.OperationalError: no such table: item_item

The above exception was the direct cause of the following exception:

Traceback (most recent call last):
  File "C:\Users\dahoon\PycharmProjects\rental\rentalService\apps\item\itemManager.py", line 20, in regist
    item.save()
  File "C:\Users\dahoon\PycharmProjects\rental\venv\lib\site-packages\django\db\models\base.py", line 718, in save
    force_update=force_update, update_fields=update_fields)
  File "C:\Users\dahoon\PycharmProjects\rental\venv\lib\site-packages\django\db\models\base.py", line 748, in save_base
    updated = self._save_table(raw, cls, force_insert, force_update, using, update_fields)
  File "C:\Users\dahoon\PycharmProjects\rental\venv\lib\site-packages\django\db\models\base.py", line 831, in _save_table
    result = self._do_insert(cls._base_manager, using, fields, update_pk, raw)
  File "C:\Users\dahoon\PycharmProjects\rental\venv\lib\site-packages\django\db\models\base.py", line 869, in _do_insert
    using=using, raw=raw)
  File "C:\Users\dahoon\PycharmProjects\rental\venv\lib\site-packages\django\db\models\manager.py", line 82, in manager_method
    return getattr(self.get_queryset(), name)(*args, **kwargs)
  File "C:\Users\dahoon\PycharmProjects\rental\venv\lib\site-packages\django\db\models\query.py", line 1136, in _insert
    return query.get_compiler(using=using).execute_sql(return_id)
  File "C:\Users\dahoon\PycharmProjects\rental\venv\lib\site-packages\django\db\models\sql\compiler.py", line 1289, in execute_sql
    cursor.execute(sql, params)
  File "C:\Users\dahoon\PycharmProjects\rental\venv\lib\site-packages\django\db\backends\utils.py", line 100, in execute
    return super().execute(sql, params)
  File "C:\Users\dahoon\PycharmProjects\rental\venv\lib\site-packages\django\db\backends\utils.py", line 68, in execute
    return self._execute_with_wrappers(sql, params, many=False, executor=self._execute)
  File "C:\Users\dahoon\PycharmProjects\rental\venv\lib\site-packages\django\db\backends\utils.py", line 77, in _execute_with_wrappers
    return executor(sql, params, many, context)
  File "C:\Users\dahoon\PycharmProjects\rental\venv\lib\site-packages\django\db\backends\utils.py", line 85, in _execute
    return self.cursor.execute(sql, params)
  File "C:\Users\dahoon\PycharmProjects\rental\venv\lib\site-packages\django\db\utils.py", line 89, in __exit__
    raise dj_exc_value.with_traceback(traceback) from exc_value
  File "C:\Users\dahoon\PycharmProjects\rental\venv\lib\site-packages\django\db\backends\utils.py", line 85, in _execute
    return self.cursor.execute(sql, params)
  File "C:\Users\dahoon\PycharmProjects\rental\venv\lib\site-packages\django\db\backends\sqlite3\base.py", line 296, in execute
    return Database.Cursor.execute(self, query, params)
django.db.utils.OperationalError: no such table: item_item

Traceback (most recent call last):
  File "C:\Users\dahoon\PycharmProjects\rental\venv\lib\site-packages\django\db\backends\utils.py", line 85, in _execute
    return self.cursor.execute(sql, params)
  File "C:\Users\dahoon\PycharmProjects\rental\venv\lib\site-packages\django\db\backends\sqlite3\base.py", line 296, in execute
    return Database.Cursor.execute(self, query, params)
sqlite3.OperationalError: no such table: item_item

The above exception was the direct cause of the following exception:

Traceback (most recent call last):
  File "C:\Users\dahoon\PycharmProjects\rental\rentalService\apps\item\itemManager.py", line 20, in regist
    item.save()
  File "C:\Users\dahoon\PycharmProjects\rental\venv\lib\site-packages\django\db\models\base.py", line 718, in save
    force_update=force_update, update_fields=update_fields)
  File "C:\Users\dahoon\PycharmProjects\rental\venv\lib\site-packages\django\db\models\base.py", line 748, in save_base
    updated = self._save_table(raw, cls, force_insert, force_update, using, update_fields)
  File "C:\Users\dahoon\PycharmProjects\rental\venv\lib\site-packages\django\db\models\base.py", line 831, in _save_table
    result = self._do_insert(cls._base_manager, using, fields, update_pk, raw)
  File "C:\Users\dahoon\PycharmProjects\rental\venv\lib\site-packages\django\db\models\base.py", line 869, in _do_insert
    using=using, raw=raw)
  File "C:\Users\dahoon\PycharmProjects\rental\venv\lib\site-packages\django\db\models\manager.py", line 82, in manager_method
    return getattr(self.get_queryset(), name)(*args, **kwargs)
  File "C:\Users\dahoon\PycharmProjects\rental\venv\lib\site-packages\django\db\models\query.py", line 1136, in _insert
    return query.get_compiler(using=using).execute_sql(return_id)
  File "C:\Users\dahoon\PycharmProjects\rental\venv\lib\site-packages\django\db\models\sql\compiler.py", line 1289, in execute_sql
    cursor.execute(sql, params)
  File "C:\Users\dahoon\PycharmProjects\rental\venv\lib\site-packages\django\db\backends\utils.py", line 100, in execute
    return super().execute(sql, params)
  File "C:\Users\dahoon\PycharmProjects\rental\venv\lib\site-packages\django\db\backends\utils.py", line 68, in execute
    return self._execute_with_wrappers(sql, params, many=False, executor=self._execute)
  File "C:\Users\dahoon\PycharmProjects\rental\venv\lib\site-packages\django\db\backends\utils.py", line 77, in _execute_with_wrappers
    return executor(sql, params, many, context)
  File "C:\Users\dahoon\PycharmProjects\rental\venv\lib\site-packages\django\db\backends\utils.py", line 85, in _execute
    return self.cursor.execute(sql, params)
  File "C:\Users\dahoon\PycharmProjects\rental\venv\lib\site-packages\django\db\utils.py", line 89, in __exit__
    raise dj_exc_value.with_traceback(traceback) from exc_value
  File "C:\Users\dahoon\PycharmProjects\rental\venv\lib\site-packages\django\db\backends\utils.py", line 85, in _execute
    return self.cursor.execute(sql, params)
  File "C:\Users\dahoon\PycharmProjects\rental\venv\lib\site-packages\django\db\backends\sqlite3\base.py", line 296, in execute
    return Database.Cursor.execute(self, query, params)
django.db.utils.OperationalError: no such table: item_item

